<?xml version="1.0" encoding="utf-8"?>

<robot xmlns:xacro="http://www.ros.org/wiki/xacro">

    <xacro:property name="mecanum_wheel_mesh_file" value="file://$(find odv_description)/meshes/wheel/mecanum_wheel.dae" />
    <xacro:property name="laser_scanner_mesh_file" value="file://$(find odv_description)/meshes/sensors/laser_scanner/laser.dae" />

    <xacro:macro name="mecanum_wheel_macro" params="namespace parent_link suffix *origin *axis">
        <link name="${namespace}/mecanum_wheel${suffix}_link">
            <visual>
                <origin xyz="0 0 0" rpy="0 0 0" />
                <geometry>
                    <mesh filename="${mecanum_wheel_mesh_file}" scale="1 1 1" />
                </geometry>
            </visual>

            <collision>
                <origin xyz="0 0 0" rpy="1.570796327 0 0" />
                <geometry>
                    <cylinder radius="0.076" length="0.0524"/>
                </geometry>
            </collision>

            <inertial>
                <origin xyz="0 0 0" rpy="0 0 0" />
                <mass value="0.1" />
                <inertia ixx="0.00072883" ixy="0" ixz="0"
                         iyy="0.0013926"  iyz="0"
                         izz="0.00072883" />
            </inertial>
        </link>

        <joint name="${namespace}/mecanum_wheel${suffix}_joint" type="continuous">
            <xacro:insert_block name="origin" />
            <parent link="${parent_link}" />
            <child link="${namespace}/mecanum_wheel${suffix}_link" />
            <xacro:insert_block name="axis" />
            <limit effort="100" velocity="100" />
        </joint>

        <transmission name="${namespace}/mecanum_wheel${suffix}_joint_trans">
            <type>transmission_interface/SimpleTransmission</type>
            <joint name="${namespace}/mecanum_wheel${suffix}_joint">
                <hardwareInterface>hardware_interface/VelocityJointInterface</hardwareInterface>
            </joint>
            <actuator name="${namespace}/mecanum_wheel${suffix}_joint_motor">
                <mechanicalReduction>1</mechanicalReduction>
            </actuator>
        </transmission>

        <gazebo reference="${namespace}/mecanum_wheel${suffix}_link">
            <mu1 value="1.0"/>
            <mu2 value="1.0"/>
            <kp value="10000000.0"/>
            <kd value="1.0"/>
            <fdir1 value="1 0 0"/>
        </gazebo>

    </xacro:macro>

    <xacro:macro name="laser_scanner_macro" params="namespace parent_link suffix *origin">
        <link name="${namespace}/laser_scanner${suffix}_link">
            <visual>
                <origin xyz="0 0 0" rpy="0 0 0" />
                <geometry>
                    <mesh filename="${laser_scanner_mesh_file}" scale="1 1 1" />
                </geometry>
            </visual>
            <collision>
                <origin xyz="0 0 0" rpy="0 0 0" />
                <geometry>
                    <box size="0.06 0.06 0.087" />
                </geometry>
            </collision>
            <inertial>
                <origin xyz="0 0 0" rpy="0 0 0" />
                <mass value="0.1" />
                <inertia ixx="0" ixy="0" ixz="0" iyy="0" iyz="0" izz="0" />
            </inertial>
        </link>

        <joint name="${namespace}/laser_scanner${suffix}_joint" type="fixed">
            <xacro:insert_block name="origin" />
            <parent link="${parent_link}" />
            <child link="${namespace}/laser_scanner${suffix}_link" />
        </joint>

        <gazebo reference="${namespace}/laser_scanner${suffix}_link">
            <sensor name="laser_scanner${suffix}" type="ray">
                <pose>0 0 0 0 0 0</pose>
                <visualize>false</visualize>
                <update_rate>40</update_rate>
                <ray>
                    <scan>
                        <horizontal>
                            <samples>810</samples>
                            <resolution>1</resolution>
                            <min_angle>-2.35619449</min_angle>
                            <max_angle>2.35619449</max_angle>
                        </horizontal>
                    </scan>
                    <range>
                        <min>0.10</min>
                        <max>30.0</max>
                        <resolution>0.01</resolution>
                    </range>
                    <noise>
                        <type>gaussian</type>
                        <mean>0.0</mean>
                        <stddev>0.01</stddev>
                    </noise>
                </ray>
                <plugin filename="libgazebo_ros_laser.so" name="gazebo_ros_head_hokuyo_controller">
                    <topicName>/${namespace}/sensors/laser_scanner${suffix}</topicName>
                    <frameName>${namespace}/laser_scanner${suffix}_link</frameName>
                </plugin>
            </sensor>
        </gazebo>
    </xacro:macro>

    <xacro:macro name="imu_macro" params="namespace parent_link suffix *origin">
        <link name="${namespace}/imu${suffix}_link">
            <visual>
                <origin xyz="0 0 0" rpy="0 0 0" />
                <geometry>
                    <box size="0.01 0.01 0.01" />
                </geometry>
            </visual>
            <collision>
                <origin xyz="0 0 0" rpy="0 0 0" />
                <geometry>
                    <box size="0.01 0.01 0.01" />
                </geometry>
            </collision>
            <inertial>
                <origin xyz="0 0 0" rpy="0 0 0" />
                <mass value="0.00001" />
                <inertia ixx="0" ixy="0" ixz="0" iyy="0" iyz="0" izz="0" />
            </inertial>
        </link>

        <joint name="${namespace}/imu${suffix}_joint" type="fixed">
            <xacro:insert_block name="origin" />
            <parent link="${parent_link}" />
            <child link="${namespace}/imu${suffix}_link" />
        </joint>

        <gazebo reference="${namespace}/imu${suffix}_link">
            <gravity>true</gravity>
            <sensor>
                <always_on>true</always_on>
                <updateRate>50</updateRate>
                <visualize>false</visualize>
                <plugin name='imu_plugin' filename='libgazebo_ros_imu.so'>
                    <bodyName>${namespace}/imu${suffix}_link</bodyName>
                    <topicName>/${namespace}/sensors/imu${suffix}/data</topicName>
                    <gaussianNoise>0.0</gaussianNoise>
                </plugin>
            </sensor>
        </gazebo>
    </xacro:macro>

</robot>